Workbook

Sheet Read me
A1: OppTrack — Work Breakdown Structure
A2: Opportunity Tracking Agent · 15 packages · 108 tasks
A5: Sheets
A6: WBS | B6: Every task: package, phase, status, size, what it is, what counts as done, and dependencies.
A7: Packages | B7: One row per package with live counts. All counts are COUNTIFS formulas over the WBS sheet.
A8: Blocked | B8: The ten blocked tasks and what each one waits on.
A10: Numbering
A11: Order | B11: The numbering is dependency order, not preference. 2.0 blocks most of what follows; 9.0 blocks the learning half of 6.0.
A13: Status
A14: Done | B14: Code exists and is covered by a test. Only 5.1, 7.6 and 7.8 qualify today.
A15: Partial | B15: A working implementation exists in the POC or bench, but not in the shape the platform needs.
A16: To do | B16: Not started, and nothing prevents starting.
A17: Blocked | B17: Waiting on a decision, a field that does not exist, or history that has not accumulated.
A19: Size
A20: S / M / L / XL | B20: Roughly: under a day / a few days / one to two weeks / longer. Engineering estimates for one developer, not committed dates.
A22: Phases
A23: 0 Read-only | B23: Intake, normalise, validate, findings. No database, no auth, no model.
A24: 1 Numbers | B24: Calc engine, roll-ups, six live analyses.
A25: 2 Identity | B25: Postgres, opportunity ID, state_history, SSO, roles, region scope.
A26: 3 Judgment | B26: Memory tiers, evidence assembler, judgment engine, review queue, audit.
A27: 4 Learning | B27: Calibration, POS and ERP connectors, forecast accuracy.
A28: 5 Outside-in | B28: Market data, EAU cross-check, white-space detection.
A30: Editing this file
A31: Owner, Due, Notes | B31: Columns J, K and L on the WBS sheet are empty and intended for you to fill in. Everything else is generated.
A32: Source | B32: Generated from OppTrack_Work_Breakdown.html, 2026-08-27. Re-generate rather than hand-editing the other columns.

Sheet WBS
A1: WBS | B1: Package | C1: Phase | D1: Task | E1: Status | F1: Size | G1: What it is | H1: Done when | I1: Depends on / blocks | J1: Owner | K1: Due | L1: Notes
A2: 1.0 | B2: Project control and stakeholder resolution | C2: Ongoing
A3: 1.1 | C3: Ongoing | D3: Send the four blocking questions | E3: Blocked | F3: S | G3: Q1 ratify the Matrix A baseline per valid (Design Status, Stage) cell. Q2 set the confidence ceiling — if a design win is not 1.00, what is the maximum any record may carry, and roughly how many points should dual sourcing or cancellation risk remove. Q3 does a person gate an auto-move to Mass Production or Design Lost. Q4 which workbook is current. Q1 and Q2 are the expensive ones. Without Q1 the agent invents a confidence number rather than justifying a deviation from an agreed one, and the file itself contradicts the stage-driven rule: three Evaluation-at-EVT rows carry 0.30, 0.50 and 0.50. Without Q2 the clamp discards every positive adjustment, so the calibrated total can only ever move down. | H3: All four answered in writing and recorded in the open-questions register, with the Matrix A table signed off cell by cell. | I3: unblocks 2.3, 2.4, 4.3, 7.3, 8.3 · owner: Akanksha
A4: 1.2 | C4: Ongoing | D4: Confirm the current workbook | E4: To do | F4: S | G4: David refers to "the sheet I updated"; our copy still contains the Projection/Stretch block his does not. Validation rules get written against a specific file, so writing them against the wrong one wastes the whole of package 4.0. Low risk in itself — that block is the only stated difference — but it has to be settled before rules are authored. Note while confirming: the #REF! roll-up rows are not pending fixes. They were broken deliberately when the forecast moved to a separate agent, and a validation rule that flags them as errors will produce noise on every run. | H4: One file is named as canonical, hashed, and stored as the Phase 0 fixture. | I4: blocks 3.1, 4.1, 12.6
A5: 1.3 | C5: Ongoing | D5: Maintain the open-questions register | E5: Partial | F5: S | G5: Currently 6 answered, 7 partly answered, 15 open, 4 internal. The register is the artefact that stops a partly-answered question being treated as settled — the auto-move policy is the live example, where two answers given separately combine to mean nobody signs off before an opportunity is closed as lost, which is almost certainly not what anyone intended. | H5: Every open item has an owner and a date, and partial answers are marked as partial rather than closed. | I5: ongoing
A6: 1.4 | C6: Ongoing | D6: Settle the four internal decisions | E6: To do | F6: S | G6: Service signature for the two POC modules, when the audit log is written relative to the decision returning, the exact rubric wording published to reviewers, and the intake field list. These need no external input, only a decision, and each one diverges the codebase if left open. | H6: Written into the repo as decisions with dates, not held in conversation. | I6: blocks 7.1, 8.2, 10.2
A7: 1.5 | C7: Ongoing | D7: Agree the intake field list with the UI owner | E7: To do | F7: S | G7: Must be settled before the form and the service diverge. It has to include Opportunity ID, owner, Unit/Set, competitor part number and loss reason — the five fields whose absence currently blocks a rubric factor or a join. Agreeing it late means either the form or the schema gets rebuilt. | H7: One schema document signed off by both the service and UI owners, covering all four intake paths, not only the form. | I7: blocks 10.3, 11.1 · owners: Lokesh + Dimple
A8: 1.6 | C8: Ongoing | D8: Agree the ROI Agent cross-validation contract | E8: To do | F8: M | G8: The ROI Agent consumes this agent's Adjusted Revenue as its revenue-forecast input. Fix the shape once, shared, rather than having both sides invent it: which figure, at what grain, carrying which snapshot identifier, and what happens when the two disagree. Without a snapshot ID on the hand-off the two agents will eventually present different totals for the same month and nobody will be able to say which is stale. | H8: A written contract exists and both agents' tests assert against the same fixture. | I8: blocks 10.9, 11.5
A9: 2.0 | B9: Parameter registry and canonical model | C9: Phase 0
A10: 2.1 | C10: Phase 0 | D10: ParamSpec for every parameter | E10: To do | F10: M | G10: One frozen dataclass per parameter: id, name, dtype, unit, enum, required, which tabs supply it, and whether it is present in the current file. Twenty-eight live entries plus the twenty-six proposed ones, so a proposed parameter is registered as absent rather than missing. The rule that makes this worth doing: nothing downstream may reference a spreadsheet column name. Rules and analyses cite V1, never column K, so a sheet reshuffle is an intake change and not a codebase change. | H10: Every parameter in the dictionary has a spec, and a test asserts the registry covers every column the intake reads. | I10: blocks 2.5, 3.6, 4.1, 6.1, 7.2
A11: 2.2 | C11: Phase 0 | D11: Canonical enums | E11: To do | F11: S | G11: Region, design status, stage, product line, application and loss reason, each with its accepted variants. This is where KR becomes Korea and D-IN becomes Design In. It has to exist before the roll-ups are rebuilt, because a regional total computed over EU and Europe as separate keys is wrong in a way nobody notices. Open item to resolve inside this task: the file holds EU, KR and North America, none of which appear on David's region list. Confirm the mapping, including whether North America means US only. | H11: Every enum value in the real file maps to exactly one canonical value, with no fallthrough. | I11: blocks 3.4, 5.3
A12: 2.3 | C12: Phase 0 | D12: Matrix A as versioned config | E12: Blocked | F12: S | G12: Valid pairings plus baseline confidence per cell, stored as a published version with an ID, not as a constant in a module. The bench already carries a proposed table; this task turns it into ratified, versioned configuration that a run records against every proposal it produces. Also needs deciding here: whether MP is a legal Stage value at all, given the Stage column in the file holds only Concept, EVT, DVT and PVT. | H12: The table is published with a version ID and a run stamps that ID on every event. | I12: blocked on 1.1 (Q1, Q2) · blocks 4.3, 7.3, 10.7
A13: 2.4 | C13: Phase 0 | D13: Opportunity ID scheme and backfill plan | E13: Blocked | F13: M | G13: The single highest-value item in the whole plan. Five cross-tab relations do not exist today because no two tabs share a key; all five close with one stable ID written on every row of every tab. This task covers the format, who issues it, and the one-time backfill of existing rows. Cheap to build, awkward to agree, and nothing that depends on joining tabs can be automated until it lands. It should be treated as the project's first deliverable, not a schema detail. | H13: Every row in the canonical workbook carries an ID and the five joins are computed rather than eyeballed. | I13: blocked on 1.1 (identity questions) · blocks 9.1, 9.2, 11.3
A14: 2.5 | C14: Phase 0 | D14: Registry-driven runnable() | E14: To do | F14: S | G14: A single function that answers, for any module, whether the parameters it declared are present in the current snapshot. This is the mechanism behind the whole not-assessable behaviour: an analysis or rubric factor whose inputs are absent reports that it cannot run, rather than running on nulls and producing a confident number from nothing. | H14: Every analysis and rubric factor reports runnable or not, and the run output lists which are dark and why. | I14: depends on 2.1 · blocks 6.1, 7.2
A15: 2.6 | C15: Phase 0 | D15: Reason-code vocabulary | E15: To do | F15: S | G15: Closed lists for loss reason, stage-exit reason and override reason. These are the labels the calibration model will eventually learn from, so a free-text field here costs a year: outcomes recorded as prose cannot be aggregated into owner bias without re-reading them by hand. | H15: The lists are agreed and enforced at the API, not just offered in a dropdown. | I15: blocks 8.4, 6.5, 11.2
A16: 3.0 | B16: Intake and normalisation | C16: Phase 0
A17: 3.1 | C17: Phase 0 | D17: Workbook reader | E17: To do | F17: M | G17: Handles the two-row header on rows 3 and 4, and the shifted column letters on the terminal tabs. Reads six tabs into raw rows with no interpretation applied. This is import-path work, not the primary intake — direct entry is — but it is how the current book of business gets in and how Phase 0 demonstrates value before any platform exists. | H17: All six tabs read into raw rows with the header quirks handled and no silent column drift. | I17: depends on 1.2 · blocks 4.5, 10.11
A18: 3.2 | C18: Phase 0 | D18: Snapshot writer | E18: To do | F18: S | G18: Write-once record of one run's input: sha256 of the source, source URI, row count per tab, timestamp. This is L1 episodic memory and the thing that makes a run reproducible — without it, "re-run last month" means re-reading a file that may have changed underneath you. | H18: A snapshot cannot be modified after sealing, and two runs over the same snapshot produce byte-identical calc output. | I18: blocks 12.4, 9.7
A19: 3.3 | C19: Phase 0 | D19: Coercion | E19: To do | F19: S | G19: Dec'24 and June'27 to dates, TBD to null, thousands separators to float, percentages to fractions. The important behaviour is that TBD becomes null and is reported, not defaulted to zero — seven numeric fields in the current file carry TBD, and a zero there silently deflates a regional total. | H19: Every coercion is reversible to the source string, which is what the milestone factor must cite. | I19: blocks 4.4, 6.3
A20: 3.4 | C20: Phase 0 | D20: Canonicalisation | E20: To do | F20: S | G20: Applies the enums from 2.2 to real values: KR to Korea, MOBIS to Mobis, D-IN to Design In, M/P to Mass Production. An unmapped value is a finding, never a new category invented at read time. | H20: The regional roll-up over the real file produces three regions, not five spellings of three regions. | I20: depends on 2.2 · blocks 5.3
A21: 3.5 | C21: Phase 0 | D21: NRE line splitter | E21: To do | F21: M | G21: Seven of ten FCST_Revenue rows are non-recurring engineering charges sitting in the volume columns. They are not silicon revenue and must not be phased like it. This task lifts them into their own record type so C10 can recognise NRE by quarter separately from unit revenue. Left unsplit, every quarterly revenue figure is inflated by one-off charges, and the error is invisible because the totals still tie to the sheet. | H21: Volume revenue and NRE reconcile separately to the workbook, and their sum ties to the original column. | I21: blocks 5.4
A22: 3.6 | C22: Phase 0 | D22: Provenance wrapper | E22: To do | F22: M | G22: FieldValue(param, value, source, at, trust) on every value, from every path. This is what the Opportunities list renders as source badges, what the precedence ladder arbitrates over, and what lets a reviewer answer "who put that there" without opening a log. | H22: No value reaches the calc engine without a source and a trust level attached. | I22: depends on 2.1 · blocks 10.4, 11.1, 11.2
A23: 3.7 | C23: Phase 0 | D23: Direct-entry intake service | E23: To do | F23: M | G23: The primary path, and the one the earlier documents under-specify because they all read the workbook. Accepts a single opportunity from the form or API, applies the same coercion, canonicalisation and validation as a bulk read, and captures owner, region and the confidence rationale at source. Values it writes carry the highest trust level, above every connector. | H23: A row created through the form is indistinguishable downstream from one imported, except that its provenance says a person entered it. | I23: depends on 1.5, 3.3, 3.4, 3.6 · blocks 10.3
A24: 4.0 | B24: Validation and findings engine | C24: Phase 0
A25: 4.1 | C25: Phase 0 | D25: One rule per finding | E25: To do | F25: L | G25: Rules V-a through V-i, each declaring the parameters it requires so it goes dark rather than throwing when a field is absent. Rules are data-quality checks, not judgment: they answer whether the file is internally consistent, and every one of them must be explainable to a sales owner in a sentence. | H25: Each rule has a passing and a failing fixture drawn from the real file. | I25: depends on 2.1, 1.2 · blocks 4.5
A26: 4.2 | C26: Phase 0 | D26: Blocking vs advisory severity | E26: To do | F26: S | G26: A blocking finding excludes the row from totals and counts it separately; an advisory one annotates and lets it through. The distinction matters more than it sounds: a design win worth zero silently included in a weighted total is how a forecast becomes wrong without anyone editing a number. | H26: Roll-ups report an included total, an excluded count, and never blend the two. | I26: blocks 5.3, 10.2
A27: 4.3 | C27: Phase 0 | D27: Matrix A pairing check | E27: Blocked | F27: S | G27: Rejects, corrects or flags a row whose (Design Status, Stage) combination is forbidden. The check itself is a table lookup; what is undecided is the behaviour on failure, and that is a policy question, not an engineering one — rejecting at intake stops bad data entering, flagging lets a real edge case through with a warning. | H27: The agreed behaviour is implemented at both intake paths, form and import, identically. | I27: blocked on 1.1 (Q1 and invalid-pairing policy) · depends on 2.3
A28: 4.4 | C28: Phase 0 | D28: Cross-tab contradiction checks | E28: To do | F28: M | G28: The two EAU definitions (ID801 reads 57,175 Kpcs on Funnel and 1,343 on FCST_Revenue), SoP dates that disagree across sheets, and totals that do not compute. These are the checks that most need the Opportunity ID from 2.4 — without a shared key they can only compare rows a human has paired up. | H28: Every contradiction in the current file is reproduced as a generated finding rather than a documented observation. | I28: depends on 2.4, 3.3
A29: 4.5 | C29: Phase 0 | D29: Findings report renderer | E29: To do | F29: M | G29: The Phase 0 deliverable: the data-quality section of the specification, generated from the file instead of written by hand. Runs with no database, no auth and no model, which is what makes it demonstrable before any platform decision is made. | H29: All twelve documented findings are reproduced from the real workbook by running one command. | I29: depends on 3.1, 4.1 · blocks 10.11
A30: 4.6 | C30: Phase 0 | D30: Dry-run validation for bulk import | E30: To do | F30: M | G30: Runs the full rule set against a proposed import and shows what would fail, before anything commits. Column mapping is confirmed by a person, the preview lists blocking and advisory findings per row, and nothing is written until the mapping is accepted. | H30: An import with a bad mapping can be abandoned with zero rows written and zero side effects. | I30: depends on 4.1 · blocks 10.11
A31: 5.0 | B31: Calculation engine | C31: Phase 1
A32: 5.1 | C32: Phase 1 | D32: C1, C2 and T2 | E32: Done | G32: Sales revenue as EAU times distributor ASP, adjusted revenue as sales revenue times confidence, and quarterly revenue as quarterly units times ASP. Implemented in calc_engine.py and asserted against the workbook's own numbers for all nine sample projects by test_calc_engine.py. | H32: Already met. The test is the contract: if it fails, the financial maths changed, and that should never happen silently.
A33: 5.2 | C33: Phase 1 | D33: C3 to C7 | E33: To do | F33: M | G33: Set volume, attach rate, channel margin in currency and percent, and part-level demand. None of these exist in the workbook; they are figures the sheet collects the inputs for and never computes. Channel margin in particular turns Resale ASP from a dead-end column into something that feeds an analysis and a rubric factor. | H33: Each has a regression assertion, and attach rate reconciles against the Unit/Set definition rather than contradicting it. | I33: depends on 5.1
A34: 5.3 | C34: Phase 1 | D34: C8, C9 and C12 roll-ups | E34: Partial | F34: M | G34: Regional roll-up rebuilt on canonical regions, stage roll-up by funnel stage, and concentration shares by every dimension at once: row, customer, end customer and part. A basic version exists in portfolio_rollup; this extends it to the full dimension set and to the exclusion behaviour from 4.2. Concentration is the analysis with the most immediate value and the least new data. The current file already shows one project carrying 48% of the Korea pipeline, and no existing report says so. | H34: Roll-up totals tie to row-level sums and excluded rows are reported separately rather than dropped. | I34: depends on 3.4, 4.2
A35: 5.4 | C35: Phase 1 | D35: C10 NRE recognition by quarter | E35: To do | F35: M | G35: Recognises non-recurring engineering separately from silicon volume, by quarter. Depends entirely on the splitter in 3.5; until that lands, every quarterly revenue figure carries one-off charges phased as though they were units. | H35: NRE and volume revenue are reported separately and sum to the workbook's original figure. | I35: depends on 3.5
A36: 5.5 | C36: Phase 1 | D36: C11 quarterly phasing rule | E36: Blocked | F36: M | G36: How one annual EAU becomes quarterly revenue: flat across four quarters, a ramp from the M/P date, or driven by programme build data. Undecided, and it matters because automotive sockets run several years at varying volume while the ROI hand-off expects a year list. Related open question to settle here: whether each opportunity needs a per-year volume profile rather than one annual figure. If it does, this is a schema change and not a formula. | H36: One rule is chosen, implemented, and its assumption stated on every export that uses it. | I36: blocked on the phasing decision and 1.6
A37: 5.6 | C37: Phase 1 | D37: Extend the regression suite | E37: To do | F37: M | G37: Every new output from 5.2 to 5.5 gets an assertion against the workbook or, where the workbook never computed it, against a hand-worked example checked by a second person. The existing test is the pattern; the discipline is that no calculation ships without one. | H37: The suite covers every C-number the product displays. | I37: depends on 5.2–5.5 · rolls into 12.1
A38: 5.7 | C38: Phase 1 | D38: Scenario recompute service | E38: To do | F38: S | G38: Takes a set of confidence overrides and returns recomputed roll-ups without persisting anything. It backs the assistant's what-if answers, the review console's preview of an approval, and the rubric editor's impact estimate. One implementation, three consumers, which is what stops those three disagreeing in front of a customer. | H38: A scenario call leaves no trace in the database and returns the same numbers a real approval would produce. | I38: depends on 5.3 · blocks 10.5, 10.7, 14.3
A39: 6.0 | B39: Analysis registry | C39: Phase 1
A40: 6.1 | C40: Phase 1 | D40: Analysis protocol and registry | E40: To do | F40: S | G40: A protocol with a requires declaration, and a registry that discovers modules and decides which may run against the current snapshot. Same mechanism as 2.5, applied to analyses: the run output should list what ran, what was dark, and which parameter was missing. | H40: Adding an analysis module requires no registration code, only a requires declaration. | I40: depends on 2.1, 2.5
...

Sheet Packages
A1: WBS | B1: Package | C1: Phase | D1: Tasks | E1: Done | F1: Partial | G1: To do | H1: Blocked | I1: % complete | J1: What it delivers
A2: 1.0 | B2: Project control and stakeholder resolution | C2: Ongoing | D2: =COUNTIF(WBS!$A$2:$A$124,"1."&"*")-COUNTIF(WBS!$A$2:$A$124,"1.0") -> 6 | E2: =COUNTIFS(WBS!$A$2:$A$124,"1."&"*",WBS!$E$2:$E$124,"Done") -> 0 | F2: =COUNTIFS(WBS!$A$2:$A$124,"1."&"*",WBS!$E$2:$E$124,"Partial") -> 1 | G2: =COUNTIFS(WBS!$A$2:$A$124,"1."&"*",WBS!$E$2:$E$124,"To do") -> 4 | H2: =COUNTIFS(WBS!$A$2:$A$124,"1."&"*",WBS!$E$2:$E$124,"Blocked") -> 1 | I2: =IF(D2=0,0,(E2+0.5*F2)/D2) -> 0.083333333 | J2: Four answers and a confirmed source file. Releases 2.3, 2.4, 4.3 and 8.3, and unfreezes tuning of 7.3.
A3: 2.0 | B3: Parameter registry and canonical model | C3: Phase 0 | D3: =COUNTIF(WBS!$A$2:$A$124,"2."&"*")-COUNTIF(WBS!$A$2:$A$124,"2.0") -> 6 | E3: =COUNTIFS(WBS!$A$2:$A$124,"2."&"*",WBS!$E$2:$E$124,"Done") -> 0 | F3: =COUNTIFS(WBS!$A$2:$A$124,"2."&"*",WBS!$E$2:$E$124,"Partial") -> 0 | G3: =COUNTIFS(WBS!$A$2:$A$124,"2."&"*",WBS!$E$2:$E$124,"To do") -> 4 | H3: =COUNTIFS(WBS!$A$2:$A$124,"2."&"*",WBS!$E$2:$E$124,"Blocked") -> 2 | I3: =IF(D3=0,0,(E3+0.5*F3)/D3) -> 0 | J3: The parameter registry every other layer declares against, canonical enums, Matrix A as versioned config, and the Opportunity ID.
A4: 3.0 | B4: Intake and normalisation | C4: Phase 0 | D4: =COUNTIF(WBS!$A$2:$A$124,"3."&"*")-COUNTIF(WBS!$A$2:$A$124,"3.0") -> 7 | E4: =COUNTIFS(WBS!$A$2:$A$124,"3."&"*",WBS!$E$2:$E$124,"Done") -> 0 | F4: =COUNTIFS(WBS!$A$2:$A$124,"3."&"*",WBS!$E$2:$E$124,"Partial") -> 0 | G4: =COUNTIFS(WBS!$A$2:$A$124,"3."&"*",WBS!$E$2:$E$124,"To do") -> 7 | H4: =COUNTIFS(WBS!$A$2:$A$124,"3."&"*",WBS!$E$2:$E$124,"Blocked") -> 0 | I4: =IF(D4=0,0,(E4+0.5*F4)/D4) -> 0 | J4: One canonical snapshot with provenance on every value, from all four intake paths.
A5: 4.0 | B5: Validation and findings engine | C5: Phase 0 | D5: =COUNTIF(WBS!$A$2:$A$124,"4."&"*")-COUNTIF(WBS!$A$2:$A$124,"4.0") -> 6 | E5: =COUNTIFS(WBS!$A$2:$A$124,"4."&"*",WBS!$E$2:$E$124,"Done") -> 0 | F5: =COUNTIFS(WBS!$A$2:$A$124,"4."&"*",WBS!$E$2:$E$124,"Partial") -> 0 | G5: =COUNTIFS(WBS!$A$2:$A$124,"4."&"*",WBS!$E$2:$E$124,"To do") -> 5 | H5: =COUNTIFS(WBS!$A$2:$A$124,"4."&"*",WBS!$E$2:$E$124,"Blocked") -> 1 | I5: =IF(D5=0,0,(E5+0.5*F5)/D5) -> 0 | J5: The Phase 0 deliverable: a generated data-quality report over the real workbook, with no database, auth or model.
A6: 5.0 | B6: Calculation engine | C6: Phase 1 | D6: =COUNTIF(WBS!$A$2:$A$124,"5."&"*")-COUNTIF(WBS!$A$2:$A$124,"5.0") -> 7 | E6: =COUNTIFS(WBS!$A$2:$A$124,"5."&"*",WBS!$E$2:$E$124,"Done") -> 1 | F6: =COUNTIFS(WBS!$A$2:$A$124,"5."&"*",WBS!$E$2:$E$124,"Partial") -> 1 | G6: =COUNTIFS(WBS!$A$2:$A$124,"5."&"*",WBS!$E$2:$E$124,"To do") -> 4 | H6: =COUNTIFS(WBS!$A$2:$A$124,"5."&"*",WBS!$E$2:$E$124,"Blocked") -> 1 | I6: =IF(D6=0,0,(E6+0.5*F6)/D6) -> 0.21428571 | J6: Every currency figure the product shows, plus the figures the spreadsheet collects inputs for and never computes.
A7: 6.0 | B7: Analysis registry | C7: Phase 1 | D7: =COUNTIF(WBS!$A$2:$A$124,"6."&"*")-COUNTIF(WBS!$A$2:$A$124,"6.0") -> 6 | E7: =COUNTIFS(WBS!$A$2:$A$124,"6."&"*",WBS!$E$2:$E$124,"Done") -> 0 | F7: =COUNTIFS(WBS!$A$2:$A$124,"6."&"*",WBS!$E$2:$E$124,"Partial") -> 0 | G7: =COUNTIFS(WBS!$A$2:$A$124,"6."&"*",WBS!$E$2:$E$124,"To do") -> 4 | H7: =COUNTIFS(WBS!$A$2:$A$124,"6."&"*",WBS!$E$2:$E$124,"Blocked") -> 2 | I7: =IF(D7=0,0,(E7+0.5*F7)/D7) -> 0 | J7: Six deterministic analyses that run on today data, and a run-to-run diff that attributes every change.
A8: 7.0 | B8: Judgment layer | C8: Phase 3 | D8: =COUNTIF(WBS!$A$2:$A$124,"7."&"*")-COUNTIF(WBS!$A$2:$A$124,"7.0") -> 9 | E8: =COUNTIFS(WBS!$A$2:$A$124,"7."&"*",WBS!$E$2:$E$124,"Done") -> 2 | F8: =COUNTIFS(WBS!$A$2:$A$124,"7."&"*",WBS!$E$2:$E$124,"Partial") -> 5 | G8: =COUNTIFS(WBS!$A$2:$A$124,"7."&"*",WBS!$E$2:$E$124,"To do") -> 1 | H8: =COUNTIFS(WBS!$A$2:$A$124,"7."&"*",WBS!$E$2:$E$124,"Blocked") -> 1 | I8: =IF(D8=0,0,(E8+0.5*F8)/D8) -> 0.5 | J8: A cited, capped, guarded confidence proposal from one model call. Mostly prototyped already.
A9: 8.0 | B9: Review, audit and lifecycle | C9: Phase 3 | D9: =COUNTIF(WBS!$A$2:$A$124,"8."&"*")-COUNTIF(WBS!$A$2:$A$124,"8.0") -> 7 | E9: =COUNTIFS(WBS!$A$2:$A$124,"8."&"*",WBS!$E$2:$E$124,"Done") -> 0 | F9: =COUNTIFS(WBS!$A$2:$A$124,"8."&"*",WBS!$E$2:$E$124,"Partial") -> 0 | G9: =COUNTIFS(WBS!$A$2:$A$124,"8."&"*",WBS!$E$2:$E$124,"To do") -> 6 | H9: =COUNTIFS(WBS!$A$2:$A$124,"8."&"*",WBS!$E$2:$E$124,"Blocked") -> 1 | I9: =IF(D9=0,0,(E9+0.5*F9)/D9) -> 0 | J9: The review queue and the audit log: the safety property that makes a bad run noise instead of a wrong number.
A10: 9.0 | B10: Data platform and identity | C10: Phase 2 | D10: =COUNTIF(WBS!$A$2:$A$124,"9."&"*")-COUNTIF(WBS!$A$2:$A$124,"9.0") -> 8 | E10: =COUNTIFS(WBS!$A$2:$A$124,"9."&"*",WBS!$E$2:$E$124,"Done") -> 0 | F10: =COUNTIFS(WBS!$A$2:$A$124,"9."&"*",WBS!$E$2:$E$124,"Partial") -> 0 | G10: =COUNTIFS(WBS!$A$2:$A$124,"9."&"*",WBS!$E$2:$E$124,"To do") -> 8 | H10: =COUNTIFS(WBS!$A$2:$A$124,"9."&"*",WBS!$E$2:$E$124,"Blocked") -> 0 | I10: =IF(D10=0,0,(E10+0.5*F10)/D10) -> 0 | J10: Postgres, real joins, the state_history event stream, SSO and region scope enforced in SQL.
A11: 10.0 | B11: Interfaces | C11: Phase 1–3 | D11: =COUNTIF(WBS!$A$2:$A$124,"10."&"*")-COUNTIF(WBS!$A$2:$A$124,"10.0") -> 13 | E11: =COUNTIFS(WBS!$A$2:$A$124,"10."&"*",WBS!$E$2:$E$124,"Done") -> 0 | F11: =COUNTIFS(WBS!$A$2:$A$124,"10."&"*",WBS!$E$2:$E$124,"Partial") -> 0 | G11: =COUNTIFS(WBS!$A$2:$A$124,"10."&"*",WBS!$E$2:$E$124,"To do") -> 13 | H11: =COUNTIFS(WBS!$A$2:$A$124,"10."&"*",WBS!$E$2:$E$124,"Blocked") -> 0 | I11: =IF(D11=0,0,(E11+0.5*F11)/D11) -> 0 | J11: Ten screens, the REST gateway, the MCP server, webhooks and six export formats.
A12: 11.0 | B12: Connectors | C12: Phase 2–5 | D12: =COUNTIF(WBS!$A$2:$A$124,"11."&"*")-COUNTIF(WBS!$A$2:$A$124,"11.0") -> 7 | E12: =COUNTIFS(WBS!$A$2:$A$124,"11."&"*",WBS!$E$2:$E$124,"Done") -> 0 | F12: =COUNTIFS(WBS!$A$2:$A$124,"11."&"*",WBS!$E$2:$E$124,"Partial") -> 0 | G12: =COUNTIFS(WBS!$A$2:$A$124,"11."&"*",WBS!$E$2:$E$124,"To do") -> 6 | H12: =COUNTIFS(WBS!$A$2:$A$124,"11."&"*",WBS!$E$2:$E$124,"Blocked") -> 1 | I12: =IF(D12=0,0,(E12+0.5*F12)/D12) -> 0 | J12: CRM, ERP and distributor feeds writing provenanced values under an explicit precedence ladder.
A13: 12.0 | B13: Quality | C13: Throughout | D13: =COUNTIF(WBS!$A$2:$A$124,"12."&"*")-COUNTIF(WBS!$A$2:$A$124,"12.0") -> 7 | E13: =COUNTIFS(WBS!$A$2:$A$124,"12."&"*",WBS!$E$2:$E$124,"Done") -> 0 | F13: =COUNTIFS(WBS!$A$2:$A$124,"12."&"*",WBS!$E$2:$E$124,"Partial") -> 1 | G13: =COUNTIFS(WBS!$A$2:$A$124,"12."&"*",WBS!$E$2:$E$124,"To do") -> 6 | H13: =COUNTIFS(WBS!$A$2:$A$124,"12."&"*",WBS!$E$2:$E$124,"Blocked") -> 0 | I13: =IF(D13=0,0,(E13+0.5*F13)/D13) -> 0.071428571 | J13: Proof the arithmetic matches the spreadsheet and the model path cannot write a number.
A14: 13.0 | B14: Deployment and operations | C14: Phase 2 onward | D14: =COUNTIF(WBS!$A$2:$A$124,"13."&"*")-COUNTIF(WBS!$A$2:$A$124,"13.0") -> 6 | E14: =COUNTIFS(WBS!$A$2:$A$124,"13."&"*",WBS!$E$2:$E$124,"Done") -> 0 | F14: =COUNTIFS(WBS!$A$2:$A$124,"13."&"*",WBS!$E$2:$E$124,"Partial") -> 0 | G14: =COUNTIFS(WBS!$A$2:$A$124,"13."&"*",WBS!$E$2:$E$124,"To do") -> 6 | H14: =COUNTIFS(WBS!$A$2:$A$124,"13."&"*",WBS!$E$2:$E$124,"Blocked") -> 0 | I14: =IF(D14=0,0,(E14+0.5*F14)/D14) -> 0 | J14: Containers, the seven scheduled jobs, hosted and local inference, observability and a restore drill.
A15: 14.0 | B15: Assistant | C15: Phase 3 | D15: =COUNTIF(WBS!$A$2:$A$124,"14."&"*")-COUNTIF(WBS!$A$2:$A$124,"14.0") -> 6 | E15: =COUNTIFS(WBS!$A$2:$A$124,"14."&"*",WBS!$E$2:$E$124,"Done") -> 0 | F15: =COUNTIFS(WBS!$A$2:$A$124,"14."&"*",WBS!$E$2:$E$124,"Partial") -> 0 | G15: =COUNTIFS(WBS!$A$2:$A$124,"14."&"*",WBS!$E$2:$E$124,"To do") -> 6 | H15: =COUNTIFS(WBS!$A$2:$A$124,"14."&"*",WBS!$E$2:$E$124,"Blocked") -> 0 | I15: =IF(D15=0,0,(E15+0.5*F15)/D15) -> 0 | J15: A read-only assistant that explains proposals and figures with citations, and has no tool that writes confidence.
A16: 15.0 | B16: Documentation and adoption | C16: Phase 1–3 | D16: =COUNTIF(WBS!$A$2:$A$124,"15."&"*")-COUNTIF(WBS!$A$2:$A$124,"15.0") -> 7 | E16: =COUNTIFS(WBS!$A$2:$A$124,"15."&"*",WBS!$E$2:$E$124,"Done") -> 0 | F16: =COUNTIFS(WBS!$A$2:$A$124,"15."&"*",WBS!$E$2:$E$124,"Partial") -> 1 | G16: =COUNTIFS(WBS!$A$2:$A$124,"15."&"*",WBS!$E$2:$E$124,"To do") -> 6 | H16: =COUNTIFS(WBS!$A$2:$A$124,"15."&"*",WBS!$E$2:$E$124,"Blocked") -> 0 | I16: =IF(D16=0,0,(E16+0.5*F16)/D16) -> 0.071428571 | J16: The reviewer handbook, generated rubric pages, API reference, and a region-by-region rollout.
B17: TOTAL | D17: =SUM(D2:D16) -> 108 | E17: =SUM(E2:E16) -> 3 | F17: =SUM(F2:F16) -> 9 | G17: =SUM(G2:G16) -> 86 | H17: =SUM(H2:H16) -> 10 | I17: =IF(D17=0,0,(E17+0.5*F17)/D17) -> 0.069444444

Sheet Blocked
A1: WBS | B1: Task | C1: Package | D1: Waiting on | E1: Clears with | F1: Impact when it clears
A2: 1.1 | B2: Send the four blocking questions | C2: Project control and stakeholder resolution | D2: unblocks 2.3, 2.4, 4.3, 7.3, 8.3 · owner: Akanksha | E2: Answers from David | F2: Releases 2.3, 2.4, 4.3 and 8.3, and unfreezes tuning of 7.3. Four answers, eleven consequences.
A3: 2.3 | B3: Matrix A as versioned config | C3: Parameter registry and canonical model | D3: blocked on 1.1 (Q1, Q2) | E3: 1.1 (Q1, Q2) | F3: The judgment layer stops inventing a confidence number and starts justifying a deviation from an agreed one.
A4: 2.4 | B4: Opportunity ID scheme and backfill plan | C4: Parameter registry and canonical model | D4: blocked on 1.1 (identity questions) | E4: 1.1 (identity) | F4: All five cross-tab joins become real foreign keys. The single highest-value item in the plan.
A5: 4.3 | B5: Matrix A pairing check | C5: Validation and findings engine | D5: blocked on 1.1 (Q1 and invalid-pairing policy) | E5: 1.1 (Q1 + policy) | F5: Bad status/stage pairings get caught at intake rather than surviving into a weighted total.
A6: 5.5 | B6: C11 quarterly phasing rule | C6: Calculation engine | D6: blocked on the phasing decision and 1.6 | E6: A phasing decision | F6: Quarterly revenue becomes defensible, and the ROI hand-off gets the year list it expects.
A7: 6.4 | B7: Coverage against target | C7: Analysis registry | D7: blocked: targets undefined | E7: Targets being defined | F7: Coverage against target becomes reportable. Trivial once a target number exists.
A8: 6.5 | B8: Forecast accuracy and owner calibration | C8: Analysis registry | D8: blocked on 2.6, 9.2, 11.4 and two quarters of history | E8: 2 quarters of history | F8: Owner and region bias become computable. This is what makes the agent improve rather than merely stay consistent.
A9: 7.9 | B9: Unblock J-02 and J-07 | C9: Judgment layer | D9: blocked on the competitor column reaching the tracked row | E9: A column copied | F9: J-02 fires immediately. The cheapest unblock in the whole plan: one column copied onto the tracked row.
A10: 8.3 | B10: Auto-move to Mass Production or Design Lost | C10: Review, audit and lifecycle | D10: blocked on 1.1 (Q3) | E10: 1.1 (Q3) | F10: Step 8 of a run switches on. Until then the agent proposes confidence and nothing else.
A11: 11.6 | B11: Vehicle programme data | C11: Connectors | D11: blocked: licence required | E11: A data licence | F11: J-11 EAU plausibility fires, and white-space detection becomes possible. The only recurring external cost.
A13: Count check | B13: =COUNTIF(WBS!$E$2:$E$124,"Blocked") -> 10 | C13: blocked tasks on the WBS sheet; the rows above must equal this
